<?xml version="1.0" ?>
<!-- =================================================================================== -->
<!-- |    This document was autogenerated by xacro from PanTiltMerge.xacro             | -->
<!-- |    EDITING THIS FILE BY HAND IS NOT RECOMMENDED                                 | -->
<!-- =================================================================================== -->
<robot name="PanTiltMerge">
  <material name="silver">
    <color rgba="0.700 0.700 0.700 1.000"/>
  </material>
  <transmission name="Rev11_tran">
    <type>transmission_interface/SimpleTransmission</type>
    <joint name="Rev11">
      <hardwareInterface>hardware_interface/EffortJointInterface</hardwareInterface>
    </joint>
    <actuator name="Rev11_actr">
      <hardwareInterface>hardware_interface/EffortJointInterface</hardwareInterface>
      <mechanicalReduction>1</mechanicalReduction>
    </actuator>
  </transmission>
  <transmission name="Rev12_tran">
    <type>transmission_interface/SimpleTransmission</type>
    <joint name="Rev12">
      <hardwareInterface>hardware_interface/EffortJointInterface</hardwareInterface>
    </joint>
    <actuator name="Rev12_actr">
      <hardwareInterface>hardware_interface/EffortJointInterface</hardwareInterface>
      <mechanicalReduction>1</mechanicalReduction>
    </actuator>
  </transmission>
  <gazebo>
    <plugin filename="libgazebo_ros_control.so" name="gazebo_ros_control">
      <robotNamespace>/PanTiltMerge</robotNamespace>
      <!-- <robotParam>$(find pioneer_playground)/description/urdf</robotParam> -->
      <robotSimType>gazebo_ros_control/DefaultRobotHWSim</robotSimType>
    </plugin>
  </gazebo>
  <gazebo reference="base_link">
    <material>Gazebo/Silver</material>
    <mu1>0.2</mu1>
    <mu2>0.2</mu2>
    <selfCollide>true</selfCollide>
    <gravity>true</gravity>
  </gazebo>
  <gazebo reference="Component14_1">
    <material>Gazebo/Silver</material>
    <mu1>0.2</mu1>
    <mu2>0.2</mu2>
    <selfCollide>true</selfCollide>
  </gazebo>
  <gazebo reference="Component148_1">
    <material>Gazebo/Silver</material>
    <mu1>0.2</mu1>
    <mu2>0.2</mu2>
    <selfCollide>true</selfCollide>
  </gazebo>
  <link name="world"/>
  <joint name="fixed" type="fixed">
    <parent link="world"/>
    <child link="base_link"/>
  </joint>
  <link name="base_link">
    <inertial>
      <origin rpy="0 0 0" xyz="-5.232320800743009e-09 -0.011675026445706529 -0.001243359375873323"/>
      <mass value="0.4289043067180927"/>
      <inertia ixx="0.000168" ixy="-0.0" ixz="-0.0" iyy="8.1e-05" iyz="-0.0" izz="0.000154"/>
    </inertial>
    <visual>
      <origin rpy="0 0 0" xyz="0 0 0"/>
      <geometry>
        <mesh filename="package://pioneer_playground/description/meshes/base_link.stl" scale="0.001 0.001 0.001"/>
      </geometry>
      <material name="silver"/>
    </visual>
    <collision>
      <origin rpy="0 0 0" xyz="0 0 0"/>
      <geometry>
        <mesh filename="package://pioneer_playground/description/meshes/base_link.stl" scale="0.001 0.001 0.001"/>
      </geometry>
    </collision>
  </link>
  <link name="Component14_1">
    <inertial>
      <origin rpy="0 0 0" xyz="-0.0001512609043505653 -0.0003478894806370932 0.026515354837247523"/>
      <mass value="0.386848751476802"/>
      <inertia ixx="0.000119" ixy="-0.0" ixz="0.0" iyy="0.000111" iyz="0.0" izz="6.5e-05"/>
    </inertial>
    <visual>
      <origin rpy="0 0 0" xyz="-0.0 -0.0 -0.019"/>
      <geometry>
        <mesh filename="package://pioneer_playground/description/meshes/Component14_1.stl" scale="0.001 0.001 0.001"/>
      </geometry>
      <material name="silver"/>
    </visual>
    <collision>
      <origin rpy="0 0 0" xyz="-0.0 -0.0 -0.019"/>
      <geometry>
        <mesh filename="package://pioneer_playground/description/meshes/Component14_1.stl" scale="0.001 0.001 0.001"/>
      </geometry>
    </collision>
  </link>
  <link name="Component148_1">
    <inertial>
      <origin rpy="0 0 0" xyz="0.0009536087233993468 0.01688485145444989 0.027606542091649172"/>
      <mass value="0.5157672422003375"/>
      <inertia ixx="0.000396" ixy="1e-06" ixz="-4e-06" iyy="0.000145" iyz="-3.6e-05" izz="0.000374"/>
    </inertial>
    <visual>
      <origin rpy="0 0 0" xyz="0.000202 0.019 -0.059365"/>
      <geometry>
        <mesh filename="package://pioneer_playground/description/meshes/Component148_1.stl" scale="0.001 0.001 0.001"/>
      </geometry>
      <material name="silver"/>
    </visual>
    <collision>
      <origin rpy="0 0 0" xyz="0.000202 0.019 -0.059365"/>
      <geometry>
        <mesh filename="package://pioneer_playground/description/meshes/Component148_1.stl" scale="0.001 0.001 0.001"/>
      </geometry>
    </collision>
  </link>
  <joint name="Rev11" type="continuous">
    <origin rpy="0 0 0" xyz="0.0 0.0 0.019"/>
    <parent link="base_link"/>
    <child link="Component14_1"/>
    <axis xyz="0.0 0.0 1.0"/>
  </joint>
  <joint name="Rev12" type="continuous">
    <origin rpy="0 0 0" xyz="-0.000202 -0.019 0.040365"/>
    <parent link="Component14_1"/>
    <child link="Component148_1"/>
    <axis xyz="0.0 -1.0 0.0"/>
  </joint>
</robot>

